Workbook

Sheet Summary Dashboard
A1: Credit Risk Analysis Report
A2: Credit Card, Personal Loan, Car Loan & Home Loan Portfolio | 1,000 Customer Sample (Synthetic Data)
A4: Portfolio Overview
A5: Total Customers | C5: =COUNTA('Customer Data'!A2:A1001) -> 1000
A6: Average Annual Income (INR) | C6: =ROUND(AVERAGE('Customer Data'!J2:J1001),0) -> 1420784
A7: Average Credit Score | C7: =ROUND(AVERAGE('Customer Data'!P2:P1001),0) -> 601
A8: Average Debt-to-Income Ratio | C8: =AVERAGE('Customer Data'!U2:U1001) -> 0.10583152
A9: Average Risk Score | C9: =ROUND(AVERAGE('Customer Data'!Y2:Y1001),1) -> 33.9
A10: Average Existing Products per Customer | C10: =ROUND(AVERAGE('Customer Data'!K2:K1001),2) -> 1.32
A12: Eligibility Status Breakdown
A13: Eligible | C13: =COUNTIF('Customer Data'!AA2:AA1001,"Eligible") -> 325 | D13: =C13/$C$16 -> 0.325
A14: Review | C14: =COUNTIF('Customer Data'!AA2:AA1001,"Review") -> 212 | D14: =C14/$C$16 -> 0.212
A15: Not Eligible | C15: =COUNTIF('Customer Data'!AA2:AA1001,"Not Eligible") -> 463 | D15: =C15/$C$16 -> 0.463
A16: Total | C16: =SUM(C13:C15) -> 1000
A18: Risk Category Breakdown
A19: Low | C19: =COUNTIF('Customer Data'!Z2:Z1001,"Low") -> 413 | D19: =C19/$C$22 -> 0.413
A20: Medium | C20: =COUNTIF('Customer Data'!Z2:Z1001,"Medium") -> 553 | D20: =C20/$C$22 -> 0.553
A21: High | C21: =COUNTIF('Customer Data'!Z2:Z1001,"High") -> 34 | D21: =C21/$C$22 -> 0.034
A22: Total | C22: =SUM(C19:C21) -> 1000
A24: Requested Product Mix (New Applications)
C25: Applications | D25: Eligible
A26: Credit Card | C26: =COUNTIF('Customer Data'!S2:S1001,"Credit Card") -> 250 | D26: =COUNTIFS('Customer Data'!S2:S1001,"Credit Card",'Customer Data'!AA2:AA1001,"Eligible") -> 84
A27: Personal Loan | C27: =COUNTIF('Customer Data'!S2:S1001,"Personal Loan") -> 239 | D27: =COUNTIFS('Customer Data'!S2:S1001,"Personal Loan",'Customer Data'!AA2:AA1001,"Eligible") -> 77
A28: Car Loan | C28: =COUNTIF('Customer Data'!S2:S1001,"Car Loan") -> 236 | D28: =COUNTIFS('Customer Data'!S2:S1001,"Car Loan",'Customer Data'!AA2:AA1001,"Eligible") -> 75
A29: Home Loan | C29: =COUNTIF('Customer Data'!S2:S1001,"Home Loan") -> 275 | D29: =COUNTIFS('Customer Data'!S2:S1001,"Home Loan",'Customer Data'!AA2:AA1001,"Eligible") -> 89
A32: Existing Products Held With Bank
A33: Credit Card | C33: =COUNTIF('Customer Data'!L2:L1001,"Y") -> 548
A34: Personal Loan | C34: =COUNTIF('Customer Data'!M2:M1001,"Y") -> 312
A35: Car Loan | C35: =COUNTIF('Customer Data'!N2:N1001,"Y") -> 278
A36: Home Loan | C36: =COUNTIF('Customer Data'!O2:O1001,"Y") -> 185

Sheet Customer Data
A1: Customer ID | B1: Full Name | C1: Phone Number | D1: Email ID | E1: Age | F1: Gender | G1: City | H1: Occupation | I1: Employment Type | J1: Annual Income (INR) | K1: Existing Products Count | L1: Has Credit Card | M1: Has Personal Loan | N1: Has Car Loan | O1: Has Home Loan | P1: Credit Score (300-900) | Q1: Existing Outstanding Debt | R1: Monthly EMI Outstanding (INR) | S1: Requested Loan/Product Type | T1: Requested Amount | U1: Debt-to-Income Ratio | V1: Missed Payments (12M) | W1: Credit Utilization (%) | X1: Years with Bank | Y1: Risk Score (0-100) | Z1: Risk Category | AA1: Eligibility Status | AB1: Marital Status | AC1: Number of Dependents | AD1: Residence Type | AE1: Employment Tenure (Years) | AF1: Co-Applicant Income (INR) | AG1: Total Household Income (INR) | AH1: Existing Loans (Other Banks) | AI1: Previous Default History | AJ1: Requested Tenure (Months) | AK1: Offered Interest Rate (%) | AL1: Proposed EMI (INR) | AM1: Loan-to-Income Ratio | AN1: Total Monthly Obligations (INR) | AO1: FOIR (Fixed Obligation to Income Ratio) | AP1: Collateral Value (INR) | AQ1: Loan-to-Value Ratio | AR1: Application Date | AS1: KYC Status
A2: CUST00001 | B2: Rajesh Kumar | D2: rajesh.kumar760@outlook.com | E2: 36 | F2: Male | G2: Chennai | H2: Salaried - Government | I2: Salaried | J2: 664647 | K2: 2 | L2: N | M2: Y | N2: Y | O2: N | P2: 327 | Q2: 223817.91 | R2: 3926.63 | S2: Home Loan | T2: 3349189 | U2: =IFERROR((R2*12)/J2,0) -> 0.070894114 | V2: 0 | W2: 31.4 | X2: 13.1 | Y2: =ROUND(0.4*((900-P2)/600*100)+0.3*MIN(U2*100,100)+0.2*MIN(V2*20,100)+0.1*W2,1) -> 43.5 | Z2: =IF(Y2<=30,"Low",IF(Y2<=60,"Medium","High")) -> Medium | AA2: =IF(AND(P2>=650,U2<=0.4,V2<=2,Y2<=50),"Eligible",IF(AND(P2>=550,V2<=4,Y2<=75),"Review","Not Eligible")) -> Not Eligible | AB2: Single | AC2: 0 | AD2: Owned | AE2: 4.4 | AF2: 722621 | AG2: =J2+AF2 -> 1387268 | AH2: 0 | AI2: N | AJ2: 240 | AK2: =(IF(S2="Credit Card",0.36,IF(S2="Personal Loan",0.14,IF(S2="Car Loan",0.09,0.085))))+IF(Z2="Low",0,IF(Z2="Medium",0.015,0.03)) -> 0.1 | AL2: =-PMT(AK2/12,AJ2,T2) -> 32320.399 | AM2: =IFERROR(T2/J2,0) -> 5.0390493 | AN2: =R2+AL2 -> 36247.029 | AO2: =IFERROR((AN2*12)/J2,0) -> 0.65442911 | AP2: 4561172 | AQ2: =IF(AP2>0,T2/AP2,"N/A") -> 0.73428255 | AR2: 46204 | AS2: Verified
A3: CUST00002 | B3: Aditya Yadav | D3: aditya.yadav550@gmail.com | E3: 45 | F3: Male | G3: Coimbatore | H3: Salaried - IT/Tech | I3: Salaried | J3: 1816807 | K3: 1 | L3: N | M3: N | N3: Y | O3: N | P3: 596 | Q3: 1073974 | R3: 41306.71 | S3: Credit Card | T3: 219295 | U3: =IFERROR((R3*12)/J3,0) -> 0.27283059 | V3: 0 | W3: 65.4 | X3: 5.6 | Y3: =ROUND(0.4*((900-P3)/600*100)+0.3*MIN(U3*100,100)+0.2*MIN(V3*20,100)+0.1*W3,1) -> 35 | Z3: =IF(Y3<=30,"Low",IF(Y3<=60,"Medium","High")) -> Medium | AA3: =IF(AND(P3>=650,U3<=0.4,V3<=2,Y3<=50),"Eligible",IF(AND(P3>=550,V3<=4,Y3<=75),"Review","Not Eligible")) -> Review | AB3: Married | AC3: 0 | AD3: Owned | AE3: 22.5 | AF3: 0 | AG3: =J3+AF3 -> 1816807 | AH3: 1 | AI3: N | AJ3: 18 | AK3: =(IF(S3="Credit Card",0.36,IF(S3="Personal Loan",0.14,IF(S3="Car Loan",0.09,0.085))))+IF(Z3="Low",0,IF(Z3="Medium",0.015,0.03)) -> 0.375 | AL3: =-PMT(AK3/12,AJ3,T3) -> 16113.634 | AM3: =IFERROR(T3/J3,0) -> 0.12070352 | AN3: =R3+AL3 -> 57420.344 | AO3: =IFERROR((AN3*12)/J3,0) -> 0.37926105 | AP3: 0 | AQ3: =IF(AP3>0,T3/AP3,"N/A") -> N/A | AR3: 45978 | AS3: Verified
A4: CUST00003 | B4: Vikram Khanna | D4: vikram.khanna705@rediffmail.com | E4: 35 | F4: Female | G4: Delhi | H4: Self Employed - Professional | I4: Self-Employed | J4: 434638 | K4: 1 | L4: N | M4: N | N4: Y | O4: N | P4: 880 | Q4: 228541.6 | R4: 7141.93 | S4: Personal Loan | T4: 737277 | U4: =IFERROR((R4*12)/J4,0) -> 0.19718285 | V4: 1 | W4: 89 | X4: 9.7 | Y4: =ROUND(0.4*((900-P4)/600*100)+0.3*MIN(U4*100,100)+0.2*MIN(V4*20,100)+0.1*W4,1) -> 20.1 | Z4: =IF(Y4<=30,"Low",IF(Y4<=60,"Medium","High")) -> Low | AA4: =IF(AND(P4>=650,U4<=0.4,V4<=2,Y4<=50),"Eligible",IF(AND(P4>=550,V4<=4,Y4<=75),"Review","Not Eligible")) -> Eligible | AB4: Married | AC4: 0 | AD4: Rented | AE4: 7.7 | AF4: 0 | AG4: =J4+AF4 -> 434638 | AH4: 0 | AI4: N | AJ4: 36 | AK4: =(IF(S4="Credit Card",0.36,IF(S4="Personal Loan",0.14,IF(S4="Car Loan",0.09,0.085))))+IF(Z4="Low",0,IF(Z4="Medium",0.015,0.03)) -> 0.14 | AL4: =-PMT(AK4/12,AJ4,T4) -> 25198.38 | AM4: =IFERROR(T4/J4,0) -> 1.6963013 | AN4: =R4+AL4 -> 32340.31 | AO4: =IFERROR((AN4*12)/J4,0) -> 0.89288954 | AP4: 0 | AQ4: =IF(AP4>0,T4/AP4,"N/A") -> N/A | AR4: 46007 | AS4: Pending
A5: CUST00004 | B5: Krishna Desai | C5: 9629908599 | D5: krishna.desai94@gmail.com | E5: 28 | F5: Male | G5: Kolkata | H5: Salaried - Education | I5: Salaried | J5: 566454 | K5: 1 | L5: Y | M5: N | N5: N | O5: N | P5: 866 | Q5: 292555 | R5: 24379.6 | S5: Credit Card | U5: =IFERROR((R5*12)/J5,0) -> 0.51646771 | V5: 4 | W5: 76.3 | X5: 11.6 | Y5: =ROUND(0.4*((900-P5)/600*100)+0.3*MIN(U5*100,100)+0.2*MIN(V5*20,100)+0.1*W5,1) -> 41.4 | Z5: =IF(Y5<=30,"Low",IF(Y5<=60,"Medium","High")) -> Medium | AA5: =IF(AND(P5>=650,U5<=0.4,V5<=2,Y5<=50),"Eligible",IF(AND(P5>=550,V5<=4,Y5<=75),"Review","Not Eligible")) -> Review | AB5: Married | AC5: 1 | AD5: Owned | AE5: 0.3 | AF5: 0 | AG5: =J5+AF5 -> 566454 | AH5: 1 | AI5: Y | AJ5: 18 | AK5: =(IF(S5="Credit Card",0.36,IF(S5="Personal Loan",0.14,IF(S5="Car Loan",0.09,0.085))))+IF(Z5="Low",0,IF(Z5="Medium",0.015,0.03)) -> 0.375 | AL5: =-PMT(AK5/12,AJ5,T5) -> 0 | AM5: =IFERROR(T5/J5,0) -> 0 | AN5: =R5+AL5 -> 24379.6 | AO5: =IFERROR((AN5*12)/J5,0) -> 0.51646771 | AP5: 0 | AQ5: =IF(AP5>0,T5/AP5,"N/A") -> N/A | AR5: 46154 | AS5: Verified
A6: CUST00005 | B6: Usha Mishra | C6: 9420452650 | D6: usha.mishra862@rediffmail.com | E6: 59 | F6: Male | G6: Chennai | H6: Salaried - Healthcare | I6: Salaried | J6: 977585 | K6: 2 | L6: Y | M6: N | N6: N | O6: Y | P6: 631 | Q6: 286592 | R6: 15083.8 | S6: Car Loan | T6: 944903 | U6: =IFERROR((R6*12)/J6,0) -> 0.18515587 | V6: 0 | W6: 27.9 | X6: 8.6 | Y6: =ROUND(0.4*((900-P6)/600*100)+0.3*MIN(U6*100,100)+0.2*MIN(V6*20,100)+0.1*W6,1) -> 26.3 | Z6: =IF(Y6<=30,"Low",IF(Y6<=60,"Medium","High")) -> Low | AA6: =IF(AND(P6>=650,U6<=0.4,V6<=2,Y6<=50),"Eligible",IF(AND(P6>=550,V6<=4,Y6<=75),"Review","Not Eligible")) -> Review | AB6: Married | AC6: 2 | AD6: Rented | AE6: 29.3 | AF6: 0 | AG6: =J6+AF6 -> 977585 | AH6: 0 | AI6: N | AJ6: 72 | AK6: =(IF(S6="Credit Card",0.36,IF(S6="Personal Loan",0.14,IF(S6="Car Loan",0.09,0.085))))+IF(Z6="Low",0,IF(Z6="Medium",0.015,0.03)) -> 0.09 | AL6: =-PMT(AK6/12,AJ6,T6) -> 17032.384 | AM6: =IFERROR(T6/J6,0) -> 0.96656864 | AN6: =R6+AL6 -> 32116.184 | AO6: =IFERROR((AN6*12)/J6,0) -> 0.3942309 | AP6: 1023354 | AQ6: =IF(AP6>0,T6/AP6,"N/A") -> 0.92333933 | AR6: 46165 | AS6: Verified
A7: CUST00006 | B7: Saanvi Reddy | E7: 40 | F7: Female | G7: Kanpur | H7: Business Owner | I7: Self-Employed | J7: 2470870 | K7: 4 | L7: Y | M7: Y | N7: Y | O7: Y | P7: 867 | R7: 13121.16 | S7: Credit Card | T7: 57220 | U7: =IFERROR((R7*12)/J7,0) -> 0.063724081 | V7: 2 | W7: 10.6 | X7: 1.2 | Y7: =ROUND(0.4*((900-P7)/600*100)+0.3*MIN(U7*100,100)+0.2*MIN(V7*20,100)+0.1*W7,1) -> 13.2 | Z7: =IF(Y7<=30,"Low",IF(Y7<=60,"Medium","High")) -> Low | AA7: =IF(AND(P7>=650,U7<=0.4,V7<=2,Y7<=50),"Eligible",IF(AND(P7>=550,V7<=4,Y7<=75),"Review","Not Eligible")) -> Eligible | AB7: Married | AC7: 1 | AD7: Rented | AE7: 5.5 | AF7: 0 | AG7: =J7+AF7 -> 2470870 | AH7: 0 | AI7: N | AJ7: 36 | AK7: =(IF(S7="Credit Card",0.36,IF(S7="Personal Loan",0.14,IF(S7="Car Loan",0.09,0.085))))+IF(Z7="Low",0,IF(Z7="Medium",0.015,0.03)) -> 0.36 | AL7: =-PMT(AK7/12,AJ7,T7) -> 2620.8931 | AM7: =IFERROR(T7/J7,0) -> 0.023157835 | AN7: =R7+AL7 -> 15742.053 | AO7: =IFERROR((AN7*12)/J7,0) -> 0.076452682 | AP7: 0 | AQ7: =IF(AP7>0,T7/AP7,"N/A") -> N/A | AR7: 46019 | AS7: Verified
A8: CUST00007 | B8: Preeti Malhotra | C8: 9304451095 | D8: preeti.malhotra97@gmail.com | E8: 63 | F8: Female | G8: Kanpur | H8: Salaried - Education | I8: Salaried | J8: 2024287 | K8: 1 | L8: Y | M8: N | N8: N | O8: N | P8: 400 | Q8: 73618 | R8: 1269.28 | S8: Car Loan | U8: =IFERROR((R8*12)/J8,0) -> 0.0075243086 | V8: 0 | W8: 23.1 | X8: 6.8 | Y8: =ROUND(0.4*((900-P8)/600*100)+0.3*MIN(U8*100,100)+0.2*MIN(V8*20,100)+0.1*W8,1) -> 35.9 | Z8: =IF(Y8<=30,"Low",IF(Y8<=60,"Medium","High")) -> Medium | AA8: =IF(AND(P8>=650,U8<=0.4,V8<=2,Y8<=50),"Eligible",IF(AND(P8>=550,V8<=4,Y8<=75),"Review","Not Eligible")) -> Not Eligible | AB8: Married | AC8: 1 | AD8: Owned | AE8: 27.7 | AF8: 0 | AG8: =J8+AF8 -> 2024287 | AH8: 2 | AI8: N | AJ8: 24 | AK8: =(IF(S8="Credit Card",0.36,IF(S8="Personal Loan",0.14,IF(S8="Car Loan",0.09,0.085))))+IF(Z8="Low",0,IF(Z8="Medium",0.015,0.03)) -> 0.105 | AL8: =-PMT(AK8/12,AJ8,T8) -> 0 | AM8: =IFERROR(T8/J8,0) -> 0 | AN8: =R8+AL8 -> 1269.28 | AO8: =IFERROR((AN8*12)/J8,0) -> 0.0075243086 | AP8: 624628 | AQ8: =IF(AP8>0,T8/AP8,"N/A") -> 0 | AR8: 46171 | AS8: Verified
A9: CUST00008 | B9: Sai Khanna | C9: 9909134796 | D9: sai.khanna870@yahoo.com | E9: 31 | F9: Female | G9: Chandigarh | H9: Business Owner | I9: Self-Employed | J9: 1196521 | K9: 2 | L9: N | M9: N | N9: Y | O9: Y | P9: 699 | Q9: 190393 | R9: 4643.72 | S9: Car Loan | T9: 1187110 | U9: =IFERROR((R9*12)/J9,0) -> 0.046572221 | V9: 2 | W9: 74.4 | X9: 11.8 | Y9: =ROUND(0.4*((900-P9)/600*100)+0.3*MIN(U9*100,100)+0.2*MIN(V9*20,100)+0.1*W9,1) -> 30.2 | Z9: =IF(Y9<=30,"Low",IF(Y9<=60,"Medium","High")) -> Medium | AA9: =IF(AND(P9>=650,U9<=0.4,V9<=2,Y9<=50),"Eligible",IF(AND(P9>=550,V9<=4,Y9<=75),"Review","Not Eligible")) -> Eligible | AB9: Single | AC9: 1 | AD9: Owned | AE9: 2.4 | AF9: 701803 | AG9: =J9+AF9 -> 1898324 | AH9: 0 | AI9: N | AJ9: 24 | AK9: =(IF(S9="Credit Card",0.36,IF(S9="Personal Loan",0.14,IF(S9="Car Loan",0.09,0.085))))+IF(Z9="Low",0,IF(Z9="Medium",0.015,0.03)) -> 0.105 | AL9: =-PMT(AK9/12,AJ9,T9) -> 55053.463 | AM9: =IFERROR(T9/J9,0) -> 0.9921347 | AN9: =R9+AL9 -> 59697.183 | AO9: =IFERROR((AN9*12)/J9,0) -> 0.59870758 | AP9: 1385162 | AQ9: =IF(AP9>0,T9/AP9,"N/A") -> 0.85701889 | AR9: 46152 | AS9: Verified
A10: CUST00009 | B10: Divya Patel | C10: 9161073976 | D10: divya.patel984@rediffmail.com | E10: 26 | F10: Male | G10: Bengaluru | H10: Salaried - Government | I10: Salaried | J10: 1286516 | K10: 1 | L10: Y | M10: N | N10: N | O10: N | P10: 340 | Q10: 478106.53 | R10: 12581.75 | S10: Car Loan | T10: 846865 | U10: =IFERROR((R10*12)/J10,0) -> 0.11735649 | V10: 0 | W10: 73 | X10: 3.7 | Y10: =ROUND(0.4*((900-P10)/600*100)+0.3*MIN(U10*100,100)+0.2*MIN(V10*20,100)+0.1*W10,1) -> 48.2 | Z10: =IF(Y10<=30,"Low",IF(Y10<=60,"Medium","High")) -> Medium | AA10: =IF(AND(P10>=650,U10<=0.4,V10<=2,Y10<=50),"Eligible",IF(AND(P10>=550,V10<=4,Y10<=75),"Review","Not Eligible")) -> Not Eligible | AB10: Married | AC10: 2 | AD10: Owned | AE10: 1.8 | AF10: 0 | AG10: =J10+AF10 -> 1286516 | AH10: 0 | AI10: N | AJ10: 72 | AK10: =(IF(S10="Credit Card",0.36,IF(S10="Personal Loan",0.14,IF(S10="Car Loan",0.09,0.085))))+IF(Z10="Low",0,IF(Z10="Medium",0.015,0.03)) -> 0.105 | AL10: =-PMT(AK10/12,AJ10,T10) -> 15903.252 | AM10: =IFERROR(T10/J10,0) -> 0.65826231 | AN10: =R10+AL10 -> 28485.002 | AO10: =IFERROR((AN10*12)/J10,0) -> 0.26569435 | AP10: 1057920 | AQ10: =IF(AP10>0,T10/AP10,"N/A") -> 0.80050004 | AR10: 45932 | AS10: Verified
A11: CUST00010 | B11: Sneha Nair | C11: 9242224154 | E11: 25 | F11: Male | G11: Kanpur | H11: Salaried - IT/Tech | I11: Salaried | J11: 961638 | K11: 1 | L11: Y | M11: N | N11: N | O11: N | P11: 841 | Q11: 4513.8 | R11: 96.04 | S11: Car Loan | T11: 517236 | U11: =IFERROR((R11*12)/J11,0) -> 0.0011984551 | V11: 5 | W11: 17.8 | X11: 1.9 | Y11: =ROUND(0.4*((900-P11)/600*100)+0.3*MIN(U11*100,100)+0.2*MIN(V11*20,100)+0.1*W11,1) -> 25.7 | Z11: =IF(Y11<=30,"Low",IF(Y11<=60,"Medium","High")) -> Low | AA11: =IF(AND(P11>=650,U11<=0.4,V11<=2,Y11<=50),"Eligible",IF(AND(P11>=550,V11<=4,Y11<=75),"Review","Not Eligible")) -> Not Eligible | AB11: Married | AC11: 2 | AD11: Owned | AE11: 2.5 | AF11: 0 | AG11: =J11+AF11 -> 961638 | AH11: 0 | AI11: N | AJ11: 48 | AK11: =(IF(S11="Credit Card",0.36,IF(S11="Personal Loan",0.14,IF(S11="Car Loan",0.09,0.085))))+IF(Z11="Low",0,IF(Z11="Medium",0.015,0.03)) -> 0.09 | AL11: =-PMT(AK11/12,AJ11,T11) -> 12871.44 | AM11: =IFERROR(T11/J11,0) -> 0.53786976 | AN11: =R11+AL11 -> 12967.48 | AO11: =IFERROR((AN11*12)/J11,0) -> 0.1618174 | AP11: 595381 | AQ11: =IF(AP11>0,T11/AP11,"N/A") -> 0.86874791 | AR11: 46023 | AS11: Verified
A12: CUST00011 | B12: Rekha Verma | C12: 9199104722 | D12: rekha.verma650@hotmail.com | E12: 38 | F12: Male | G12: Mumbai | H12: Salaried - Healthcare | I12: Salaried | J12: 848697 | K12: 1 | L12: N | M12: Y | N12: N | O12: N | P12: 737 | Q12: 285623.98 | R12: 15032.84 | S12: Credit Card | U12: =IFERROR((R12*12)/J12,0) -> 0.21255416 | V12: 2 | W12: 19.2 | X12: 0.7 | Y12: =ROUND(0.4*((900-P12)/600*100)+0.3*MIN(U12*100,100)+0.2*MIN(V12*20,100)+0.1*W12,1) -> 27.2 | Z12: =IF(Y12<=30,"Low",IF(Y12<=60,"Medium","High")) -> Low | AA12: =IF(AND(P12>=650,U12<=0.4,V12<=2,Y12<=50),"Eligible",IF(AND(P12>=550,V12<=4,Y12<=75),"Review","Not Eligible")) -> Eligible | AB12: Married | AC12: 2 | AD12: Owned | AE12: 1 | AF12: 0 | AG12: =J12+AF12 -> 848697 | AH12: 3 | AI12: Y | AJ12: 12 | AK12: =(IF(S12="Credit Card",0.36,IF(S12="Personal Loan",0.14,IF(S12="Car Loan",0.09,0.085))))+IF(Z12="Low",0,IF(Z12="Medium",0.015,0.03)) -> 0.36 | AL12: =-PMT(AK12/12,AJ12,T12) -> 0 | AM12: =IFERROR(T12/J12,0) -> 0 | AN12: =R12+AL12 -> 15032.84 | AO12: =IFERROR((AN12*12)/J12,0) -> 0.21255416 | AP12: 0 | AQ12: =IF(AP12>0,T12/AP12,"N/A") -> N/A | AR12: 46078 | AS12: Verified
A13: CUST00012 | B13: Rahul Pandey | D13: rahul.pandey363@rediffmail.com | E13: 47 | F13: Male | G13: Ahmedabad | H13: Self Employed - Business | I13: Self-Employed | J13: 1042611 | K13: 1 | L13: N | M13: Y | N13: N | O13: N | P13: 721 | Q13: 501851.51 | R13: 8505.96 | S13: Personal Loan | T13: 329766 | U13: =IFERROR((R13*12)/J13,0) -> 0.097899907 | V13: 0 | W13: 71.6 | X13: 5.9 | Y13: =ROUND(0.4*((900-P13)/600*100)+0.3*MIN(U13*100,100)+0.2*MIN(V13*20,100)+0.1*W13,1) -> 22 | Z13: =IF(Y13<=30,"Low",IF(Y13<=60,"Medium","High")) -> Low | AA13: =IF(AND(P13>=650,U13<=0.4,V13<=2,Y13<=50),"Eligible",IF(AND(P13>=550,V13<=4,Y13<=75),"Review","Not Eligible")) -> Eligible | AB13: Married | AC13: 1 | AD13: Owned | AE13: 23.9 | AF13: 765402 | AG13: =J13+AF13 -> 1808013 | AH13: 2 | AI13: N | AJ13: 24 | AK13: =(IF(S13="Credit Card",0.36,IF(S13="Personal Loan",0.14,IF(S13="Car Loan",0.09,0.085))))+IF(Z13="Low",0,IF(Z13="Medium",0.015,0.03)) -> 0.14 | AL13: =-PMT(AK13/12,AJ13,T13) -> 15833.016 | AM13: =IFERROR(T13/J13,0) -> 0.31628863 | AN13: =R13+AL13 -> 24338.976 | AO13: =IFERROR((AN13*12)/J13,0) -> 0.28013105 | AP13: 0 | AQ13: =IF(AP13>0,T13/AP13,"N/A") -> N/A | AR13: 46099 | AS13: Verified
A14: CUST00013 | B14: Usha Gupta | C14: 9930353157 | D14: usha.gupta286@outlook.com | E14: 62 | F14: Female | G14: Coimbatore | H14: Salaried - Healthcare | I14: Salaried | J14: 415765 | K14: 2 | L14: Y | M14: N | N14: Y | O14: N | P14: 571 | Q14: 9543.6 | R14: 190.87 | S14: Home Loan | T14: 4399833 | U14: =IFERROR((R14*12)/J14,0) -> 0.0055089774 | V14: 2 | W14: 34.8 | X14: 9.2 | Y14: =ROUND(0.4*((900-P14)/600*100)+0.3*MIN(U14*100,100)+0.2*MIN(V14*20,100)+0.1*W14,1) -> 33.6 | Z14: =IF(Y14<=30,"Low",IF(Y14<=60,"Medium","High")) -> Medium | AA14: =IF(AND(P14>=650,U14<=0.4,V14<=2,Y14<=50),"Eligible",IF(AND(P14>=550,V14<=4,Y14<=75),"Review","Not Eligible")) -> Review | AB14: Married | AC14: 1 | AD14: Rented | AE14: 7.9 | AF14: 0 | AG14: =J14+AF14 -> 415765 | AH14: 0 | AI14: Y | AJ14: 360 | AK14: =(IF(S14="Credit Card",0.36,IF(S14="Personal Loan",0.14,IF(S14="Car Loan",0.09,0.085))))+IF(Z14="Low",0,IF(Z14="Medium",0.015,0.03)) -> 0.1 | AL14: =-PMT(AK14/12,AJ14,T14) -> 38611.684 | AM14: =IFERROR(T14/J14,0) -> 10.5825 | AN14: =R14+AL14 -> 38802.554 | AO14: =IFERROR((AN14*12)/J14,0) -> 1.1199371 | AP14: 5815322 | AQ14: =IF(AP14>0,T14/AP14,"N/A") -> 0.75659319 | AR14: 46238 | AS14: Verified
A15: CUST00014 | B15: Saanvi Gupta | C15: 9813219781 | D15: saanvi.gupta943@outlook.com | E15: 60 | F15: Female | G15: Hyderabad | H15: Salaried - IT/Tech | I15: Salaried | J15: 2427025 | K15: 1 | L15: Y | M15: N | N15: N | O15: N | P15: 430 | R15: 5173.34 | S15: Home Loan | T15: 7181754 | U15: =IFERROR((R15*12)/J15,0) -> 0.025578673 | V15: 2 | W15: 21.5 | X15: 8.6 | Y15: =ROUND(0.4*((900-P15)/600*100)+0.3*MIN(U15*100,100)+0.2*MIN(V15*20,100)+0.1*W15,1) -> 42.3 | Z15: =IF(Y15<=30,"Low",IF(Y15<=60,"Medium","High")) -> Medium | AA15: =IF(AND(P15>=650,U15<=0.4,V15<=2,Y15<=50),"Eligible",IF(AND(P15>=550,V15<=4,Y15<=75),"Review","Not Eligible")) -> Not Eligible | AB15: Married | AC15: 3 | AD15: Owned | AE15: 6.5 | AF15: 0 | AG15: =J15+AF15 -> 2427025 | AH15: 1 | AI15: N | AJ15: 300 | AK15: =(IF(S15="Credit Card",0.36,IF(S15="Personal Loan",0.14,IF(S15="Car Loan",0.09,0.085))))+IF(Z15="Low",0,IF(Z15="Medium",0.015,0.03)) -> 0.1 | AL15: =-PMT(AK15/12,AJ15,T15) -> 65260.652 | AM15: =IFERROR(T15/J15,0) -> 2.9590771 | AN15: =R15+AL15 -> 70433.992 | AO15: =IFERROR((AN15*12)/J15,0) -> 0.34824854 | AP15: 9052888 | AQ15: =IF(AP15>0,T15/AP15,"N/A") -> 0.79331082 | AR15: 46004 | AS15: Verified
A16: CUST00015 | B16: Kiran Sethi | C16: 9954725078 | D16: kiran.sethi754@yahoo.com | E16: 63 | F16: Male | G16: Surat | H16: Freelancer | I16: Self-Employed | J16: 1705881 | K16: 2 | L16: Y | M16: N | N16: Y | O16: N | P16: 503 | Q16: 150821 | R16: 10772.93 | S16: Personal Loan | T16: 548216 | U16: =IFERROR((R16*12)/J16,0) -> 0.07578205 | V16: 1 | W16: 78 | X16: 6.9 | Y16: =ROUND(0.4*((900-P16)/600*100)+0.3*MIN(U16*100,100)+0.2*MIN(V16*20,100)+0.1*W16,1) -> 40.5 | Z16: =IF(Y16<=30,"Low",IF(Y16<=60,"Medium","High")) -> Medium | AA16: =IF(AND(P16>=650,U16<=0.4,V16<=2,Y16<=50),"Eligible",IF(AND(P16>=550,V16<=4,Y16<=75),"Review","Not Eligible")) -> Not Eligible | AB16: Single | AC16: 2 | AD16: Rented | AE16: 11.7 | AF16: 0 | AG16: =J16+AF16 -> 1705881 | AH16: 0 | AI16: N | AJ16: 12 | AK16: =(IF(S16="Credit Card",0.36,IF(S16="Personal Loan",0.14,IF(S16="Car Loan",0.09,0.085))))+IF(Z16="Low",0,IF(Z16="Medium",0.015,0.03)) -> 0.155 | AL16: =-PMT(AK16/12,AJ16,T16) -> 49610.487 | AM16: =IFERROR(T16/J16,0) -> 0.32136825 | AN16: =R16+AL16 -> 60383.417 | AO16: =IFERROR((AN16*12)/J16,0) -> 0.42476644 | AP16: 0 | AQ16: =IF(AP16>0,T16/AP16,"N/A") -> N/A | AR16: 46112 | AS16: Verified
A17: CUST00016 | B17: Preeti Tiwari | C17: 9656152900 | D17: preeti.tiwari476@gmail.com | E17: 56 | F17: Male | G17: Hyderabad | H17: Business Owner | I17: Self-Employed | J17: 859264 | K17: 0 | L17: N | M17: N | N17: N | O17: N | P17: 753 | Q17: 52643.01 | R17: 907.64 | S17: Home Loan | U17: =IFERROR((R17*12)/J17,0) -> 0.012675592 | V17: 0 | W17: 20.1 | X17: 13 | Y17: =ROUND(0.4*((900-P17)/600*100)+0.3*MIN(U17*100,100)+0.2*MIN(V17*20,100)+0.1*W17,1) -> 12.2 | Z17: =IF(Y17<=30,"Low",IF(Y17<=60,"Medium","High")) -> Low | AA17: =IF(AND(P17>=650,U17<=0.4,V17<=2,Y17<=50),"Eligible",IF(AND(P17>=550,V17<=4,Y17<=75),"Review","Not Eligible")) -> Eligible | AB17: Married | AC17: 2 | AD17: Rented | AE17: 8.5 | AF17: 0 | AG17: =J17+AF17 -> 859264 | AH17: 0 | AI17: N | AJ17: 300 | AK17: =(IF(S17="Credit Card",0.36,IF(S17="Personal Loan",0.14,IF(S17="Car Loan",0.09,0.085))))+IF(Z17="Low",0,IF(Z17="Medium",0.015,0.03)) -> 0.085 | AL17: =-PMT(AK17/12,AJ17,T17) -> 0 | AM17: =IFERROR(T17/J17,0) -> 0 | AN17: =R17+AL17 -> 907.64 | AO17: =IFERROR((AN17*12)/J17,0) -> 0.012675592 | AP17: 7128348 | AQ17: =IF(AP17>0,T17/AP17,"N/A") -> 0 | AR17: 46041 | AS17: Verified
A18: CUST00017 | B18: Diya Mehta | C18: 9679984033 | D18: diya.mehta83@yahoo.com | E18: 30 | F18: Male | G18: Nagpur | H18: Self Employed - Business | I18: Self-Employed | J18: 1197383 | K18: 1 | L18: Y | M18: N | N18: N | O18: N | P18: 511 | Q18: 598374 | R18: 16621.5 | S18: Credit Card | U18: =IFERROR((R18*12)/J18,0) -> 0.16657828 | V18: 4 | W18: 59.7 | X18: 7.3 | Y18: =ROUND(0.4*((900-P18)/600*100)+0.3*MIN(U18*100,100)+0.2*MIN(V18*20,100)+0.1*W18,1) -> 52.9 | Z18: =IF(Y18<=30,"Low",IF(Y18<=60,"Medium","High")) -> Medium | AA18: =IF(AND(P18>=650,U18<=0.4,V18<=2,Y18<=50),"Eligible",IF(AND(P18>=550,V18<=4,Y18<=75),"Review","Not Eligible")) -> Not Eligible | AB18: Single | AC18: 1 | AD18: Owned | AE18: 8.1 | AF18: 0 | AG18: =J18+AF18 -> 1197383 | AH18: 0 | AI18: N | AJ18: 18 | AK18: =(IF(S18="Credit Card",0.36,IF(S18="Personal Loan",0.14,IF(S18="Car Loan",0.09,0.085))))+IF(Z18="Low",0,IF(Z18="Medium",0.015,0.03)) -> 0.375 | AL18: =-PMT(AK18/12,AJ18,T18) -> 0 | AM18: =IFERROR(T18/J18,0) -> 0 | AN18: =R18+AL18 -> 16621.5 | AO18: =IFERROR((AN18*12)/J18,0) -> 0.16657828 | AP18: 0 | AQ18: =IF(AP18>0,T18/AP18,"N/A") -> N/A | AR18: 46144 | AS18: Verified
A19: CUST00018 | B19: Saanvi Joshi | C19: 9131165166 | D19: saanvi.joshi399@outlook.com | E19: 63 | F19: Female | G19: Kolkata | H19: Business Owner | I19: Self-Employed | J19: 835309 | K19: 0 | L19: N | M19: N | N19: N | O19: N | P19: 327 | Q19: 7012 | R19: 179.8 | S19: Personal Loan | T19: 958959 | U19: =IFERROR((R19*12)/J19,0) -> 0.0025829962 | V19: 1 | W19: 9.8 | X19: 5.8 | Y19: =ROUND(0.4*((900-P19)/600*100)+0.3*MIN(U19*100,100)+0.2*MIN(V19*20,100)+0.1*W19,1) -> 43.3 | Z19: =IF(Y19<=30,"Low",IF(Y19<=60,"Medium","High")) -> Medium | AA19: =IF(AND(P19>=650,U19<=0.4,V19<=2,Y19<=50),"Eligible",IF(AND(P19>=550,V19<=4,Y19<=75),"Review","Not Eligible")) -> Not Eligible | AB19: Married | AC19: 1 | AD19: Rented | AE19: 11.6 | AF19: 0 | AG19: =J19+AF19 -> 835309 | AH19: 2 | AI19: N | AJ19: 12 | AK19: =(IF(S19="Credit Card",0.36,IF(S19="Personal Loan",0.14,IF(S19="Car Loan",0.09,0.085))))+IF(Z19="Low",0,IF(Z19="Medium",0.015,0.03)) -> 0.155 | AL19: =-PMT(AK19/12,AJ19,T19) -> 86780.435 | AM19: =IFERROR(T19/J19,0) -> 1.1480291 | AN19: =R19+AL19 -> 86960.235 | AO19: =IFERROR((AN19*12)/J19,0) -> 1.2492656 | AP19: 0 | AQ19: =IF(AP19>0,T19/AP19,"N/A") -> N/A | AR19: 46135 | AS19: Verified
A20: CUST00019 | B20: Shreya Verma | C20: 9475767056 | D20: shreya.verma230@gmail.com | E20: 62 | F20: Male | G20: Mumbai | H20: Self Employed - Professional | I20: Self-Employed | J20: 1136179 | K20: 1 | L20: N | M20: N | N20: Y | O20: N | P20: 417 | Q20: 384462.24 | R20: 15378.49 | S20: Home Loan | T20: 7367537 | U20: =IFERROR((R20*12)/J20,0) -> 0.16242324 | V20: 0 | W20: 40 | X20: 9.2 | Y20: =ROUND(0.4*((900-P20)/600*100)+0.3*MIN(U20*100,100)+0.2*MIN(V20*20,100)+0.1*W20,1) -> 41.1 | Z20: =IF(Y20<=30,"Low",IF(Y20<=60,"Medium","High")) -> Medium | AA20: =IF(AND(P20>=650,U20<=0.4,V20<=2,Y20<=50),"Eligible",IF(AND(P20>=550,V20<=4,Y20<=75),"Review","Not Eligible")) -> Not Eligible | AB20: Divorced | AC20: 2 | AD20: Rented | AE20: 5.2 | AF20: 584014 | AG20: =J20+AF20 -> 1720193 | AH20: 2 | AI20: N | AJ20: 300 | AK20: =(IF(S20="Credit Card",0.36,IF(S20="Personal Loan",0.14,IF(S20="Car Loan",0.09,0.085))))+IF(Z20="Low",0,IF(Z20="Medium",0.015,0.03)) -> 0.1 | AL20: =-PMT(AK20/12,AJ20,T20) -> 66948.864 | AM20: =IFERROR(T20/J20,0) -> 6.4844862 | AN20: =R20+AL20 -> 82327.354 | AO20: =IFERROR((AN20*12)/J20,0) -> 0.86951813 | AP20: 9203259 | AQ20: =IF(AP20>0,T20/AP20,"N/A") -> 0.80053566 | AR20: 45996 | AS20: Verified
A21: CUST00020 | B21: Deepak Saxena | C21: 9773496394 | D21: deepak.saxena249@gmail.com | E21: 65 | F21: Female | G21: Hyderabad | H21: Salaried - Private | I21: Salaried | J21: 1756278 | K21: 2 | L21: Y | M21: N | N21: Y | O21: N | P21: 312 | R21: 20819.87 | S21: Credit Card | T21: 247291 | U21: =IFERROR((R21*12)/J21,0) -> 0.1422545 | V21: 6 | W21: 65.4 | X21: 12.5 | Y21: =ROUND(0.4*((900-P21)/600*100)+0.3*MIN(U21*100,100)+0.2*MIN(V21*20,100)+0.1*W21,1) -> 70 | Z21: =IF(Y21<=30,"Low",IF(Y21<=60,"Medium","High")) -> High | AA21: =IF(AND(P21>=650,U21<=0.4,V21<=2,Y21<=50),"Eligible",IF(AND(P21>=550,V21<=4,Y21<=75),"Review","Not Eligible")) -> Not Eligible | AB21: Single | AC21: 1 | AD21: Rented | AE21: 29 | AF21: 756149 | AG21: =J21+AF21 -> 2512427 | AH21: 0 | AI21: N | AJ21: 36 | AK21: =(IF(S21="Credit Card",0.36,IF(S21="Personal Loan",0.14,IF(S21="Car Loan",0.09,0.085))))+IF(Z21="Low",0,IF(Z21="Medium",0.015,0.03)) -> 0.39 | AL21: =-PMT(AK21/12,AJ21,T21) -> 11753.324 | AM21: =IFERROR(T21/J21,0) -> 0.14080402 | AN21: =R21+AL21 -> 32573.194 | AO21: =IFERROR((AN21*12)/J21,0) -> 0.22256062 | AP21: 0 | AQ21: =IF(AP21>0,T21/AP21,"N/A") -> N/A | AR21: 46198 | AS21: Verified
A22: CUST00021 | B22: Rekha Rao | C22: 9991990632 | D22: rekha.rao958@gmail.com | E22: 38 | F22: Female | G22: Ahmedabad | H22: Business Owner | I22: Self-Employed | J22: 1889596 | K22: 1 | L22: Y | M22: N | N22: N | O22: N | P22: 663 | Q22: 904548 | R22: 27410.56 | S22: Car Loan | U22: =IFERROR((R22*12)/J22,0) -> 0.17407251 | V22: 1 | W22: 54.1 | X22: 3 | Y22: =ROUND(0.4*((900-P22)/600*100)+0.3*MIN(U22*100,100)+0.2*MIN(V22*20,100)+0.1*W22,1) -> 30.4 | Z22: =IF(Y22<=30,"Low",IF(Y22<=60,"Medium","High")) -> Medium | AA22: =IF(AND(P22>=650,U22<=0.4,V22<=2,Y22<=50),"Eligible",IF(AND(P22>=550,V22<=4,Y22<=75),"Review","Not Eligible")) -> Eligible | AB22: Married | AC22: 1 | AD22: Rented | AE22: 4.3 | AF22: 0 | AG22: =J22+AF22 -> 1889596 | AH22: 1 | AI22: N | AJ22: 24 | AK22: =(IF(S22="Credit Card",0.36,IF(S22="Personal Loan",0.14,IF(S22="Car Loan",0.09,0.085))))+IF(Z22="Low",0,IF(Z22="Medium",0.015,0.03)) -> 0.105 | AL22: =-PMT(AK22/12,AJ22,T22) -> 0 | AM22: =IFERROR(T22/J22,0) -> 0 | AN22: =R22+AL22 -> 27410.56 | AO22: =IFERROR((AN22*12)/J22,0) -> 0.17407251 | AP22: 939712 | AQ22: =IF(AP22>0,T22/AP22,"N/A") -> 0 | AR22: 46008 | AS22: Verified
A23: CUST00022 | B23: Rahul Iyer | C23: 9812921644 | D23: rahul.iyer596@outlook.com | E23: 51 | F23: Female | G23: Indore | H23: Freelancer | I23: Self-Employed | J23: 1687439 | K23: 1 | L23: Y | M23: N | N23: N | O23: N | P23: 497 | Q23: 319480.74 | R23: 5414.93 | S23: Personal Loan | T23: 250845 | U23: =IFERROR((R23*12)/J23,0) -> 0.038507561 | V23: 0 | W23: 51 | X23: 10.9 | Y23: =ROUND(0.4*((900-P23)/600*100)+0.3*MIN(U23*100,100)+0.2*MIN(V23*20,100)+0.1*W23,1) -> 33.1 | Z23: =IF(Y23<=30,"Low",IF(Y23<=60,"Medium","High")) -> Medium | AA23: =IF(AND(P23>=650,U23<=0.4,V23<=2,Y23<=50),"Eligible",IF(AND(P23>=550,V23<=4,Y23<=75),"Review","Not Eligible")) -> Not Eligible | AB23: Divorced | AC23: 2 | AD23: Owned | AE23: 3.3 | AF23: 320612 | AG23: =J23+AF23 -> 2008051 | AH23: 0 | AI23: N | AJ23: 60 | AK23: =(IF(S23="Credit Card",0.36,IF(S23="Personal Loan",0.14,IF(S23="Car Loan",0.09,0.085))))+IF(Z23="Low",0,IF(Z23="Medium",0.015,0.03)) -> 0.155 | AL23: =-PMT(AK23/12,AJ23,T23) -> 6033.6227 | AM23: =IFERROR(T23/J23,0) -> 0.14865426 | AN23: =R23+AL23 -> 11448.553 | AO23: =IFERROR((AN23*12)/J23,0) -> 0.081414873 | AP23: 0 | AQ23: =IF(AP23>0,T23/AP23,"N/A") -> N/A | AR23: 45959 | AS23: Verified
A24: CUST00023 | B24: Vihaan Bhatt | C24: 9413679331 | D24: vihaan.bhatt715@yahoo.com | E24: 61 | F24: Female | G24: Hyderabad | H24: Salaried - Private | I24: Salaried | J24: 1492605 | K24: 3 | L24: Y | M24: N | N24: Y | O24: Y | P24: 789 | Q24: 102172 | R24: 6385.76 | S24: Home Loan | T24: 5625069 | U24: =IFERROR((R24*12)/J24,0) -> 0.051339182 | V24: 0 | W24: 64.8 | X24: 1 | Y24: =ROUND(0.4*((900-P24)/600*100)+0.3*MIN(U24*100,100)+0.2*MIN(V24*20,100)+0.1*W24,1) -> 15.4 | Z24: =IF(Y24<=30,"Low",IF(Y24<=60,"Medium","High")) -> Low | AA24: =IF(AND(P24>=650,U24<=0.4,V24<=2,Y24<=50),"Eligible",IF(AND(P24>=550,V24<=4,Y24<=75),"Review","Not Eligible")) -> Eligible | AB24: Married | AC24: 2 | AD24: Owned | AE24: 29.8 | AF24: 723333 | AG24: =J24+AF24 -> 2215938 | AH24: 1 | AI24: N | AJ24: 180 | AK24: =(IF(S24="Credit Card",0.36,IF(S24="Personal Loan",0.14,IF(S24="Car Loan",0.09,0.085))))+IF(Z24="Low",0,IF(Z24="Medium",0.015,0.03)) -> 0.085 | AL24: =-PMT(AK24/12,AJ24,T24) -> 55392.28 | AM24: =IFERROR(T24/J24,0) -> 3.7686253 | AN24: =R24+AL24 -> 61778.04 | AO24: =IFERROR((AN24*12)/J24,0) -> 0.49667291 | AP24: 7559662 | AQ24: =IF(AP24>0,T24/AP24,"N/A") -> 0.74409001 | AR24: 46089 | AS24: Verified
A25: CUST00024 | B25: Tanya Iyer | C25: 9731924051 | D25: tanya.iyer440@outlook.com | E25: 57 | F25: Male | G25: Hyderabad | H25: Self Employed - Professional | I25: Self-Employed | J25: 1185103 | K25: 3 | L25: Y | M25: Y | N25: Y | O25: N | P25: 460 | Q25: 1902.6 | R25: 47.56 | S25: Home Loan | T25: 3943260 | U25: =IFERROR((R25*12)/J25,0) -> 0.00048157839 | V25: 0 | W25: 32.4 | X25: 4.4 | Y25: =ROUND(0.4*((900-P25)/600*100)+0.3*MIN(U25*100,100)+0.2*MIN(V25*20,100)+0.1*W25,1) -> 32.6 | Z25: =IF(Y25<=30,"Low",IF(Y25<=60,"Medium","High")) -> Medium | AA25: =IF(AND(P25>=650,U25<=0.4,V25<=2,Y25<=50),"Eligible",IF(AND(P25>=550,V25<=4,Y25<=75),"Review","Not Eligible")) -> Not Eligible | AB25: Single | AC25: 0 | AD25: Owned | AE25: 8.2 | AF25: 0 | AG25: =J25+AF25 -> 1185103 | AH25: 1 | AI25: N | AJ25: 180 | AK25: =(IF(S25="Credit Card",0.36,IF(S25="Personal Loan",0.14,IF(S25="Car Loan",0.09,0.085))))+IF(Z25="Low",0,IF(Z25="Medium",0.015,0.03)) -> 0.1 | AL25: =-PMT(AK25/12,AJ25,T25) -> 42374.474 | AM25: =IFERROR(T25/J25,0) -> 3.3273564 | AN25: =R25+AL25 -> 42422.034 | AO25: =IFERROR((AN25*12)/J25,0) -> 0.42955288 | AP25: 4953857 | AQ25: =IF(AP25>0,T25/AP25,"N/A") -> 0.79599795 | AR25: 46173 | AS25: Verified
A26: CUST00025 | B26: Ishaan Khanna | D26: ishaan.khanna847@yahoo.com | E26: 25 | F26: Male | G26: Kolkata | H26: Salaried - IT/Tech | I26: Salaried | J26: 1510520 | K26: 1 | L26: Y | M26: N | N26: N | O26: N | P26: 578 | R26: 10548.46 | S26: Home Loan | T26: 2174795 | U26: =IFERROR((R26*12)/J26,0) -> 0.083799963 | V26: 1 | W26: 89.5 | X26: 11.1 | Y26: =ROUND(0.4*((900-P26)/600*100)+0.3*MIN(U26*100,100)+0.2*MIN(V26*20,100)+0.1*W26,1) -> 36.9 | Z26: =IF(Y26<=30,"Low",IF(Y26<=60,"Medium","High")) -> Medium | AA26: =IF(AND(P26>=650,U26<=0.4,V26<=2,Y26<=50),"Eligible",IF(AND(P26>=550,V26<=4,Y26<=75),"Review","Not Eligible")) -> Review | AB26: Single | AC26: 0 | AD26: Owned | AE26: 2.8 | AF26: 0 | AG26: =J26+AF26 -> 1510520 | AH26: 1 | AI26: N | AJ26: 240 | AK26: =(IF(S26="Credit Card",0.36,IF(S26="Personal Loan",0.14,IF(S26="Car Loan",0.09,0.085))))+IF(Z26="Low",0,IF(Z26="Medium",0.015,0.03)) -> 0.1 | AL26: =-PMT(AK26/12,AJ26,T26) -> 20987.242 | AM26: =IFERROR(T26/J26,0) -> 1.4397658 | AN26: =R26+AL26 -> 31535.702 | AO26: =IFERROR((AN26*12)/J26,0) -> 0.25052858 | AP26: 2814319 | AQ26: =IF(AP26>0,T26/AP26,"N/A") -> 0.77276066 | AR26: 45984 | AS26: Verified
A27: CUST00026 | B27: Suresh Kapoor | C27: 9398668350 | D27: suresh.kapoor186@rediffmail.com | E27: 48 | F27: Female | G27: Bengaluru | H27: Business Owner | I27: Self-Employed | J27: 1759454 | K27: 3 | L27: Y | M27: N | N27: Y | O27: Y | P27: 721 | R27: 24409.74 | S27: Home Loan | U27: =IFERROR((R27*12)/J27,0) -> 0.16648169 | V27: 1 | W27: 48.2 | X27: 4.9 | Y27: =ROUND(0.4*((900-P27)/600*100)+0.3*MIN(U27*100,100)+0.2*MIN(V27*20,100)+0.1*W27,1) -> 25.7 | Z27: =IF(Y27<=30,"Low",IF(Y27<=60,"Medium","High")) -> Low | AA27: =IF(AND(P27>=650,U27<=0.4,V27<=2,Y27<=50),"Eligible",IF(AND(P27>=550,V27<=4,Y27<=75),"Review","Not Eligible")) -> Eligible | AB27: Married | AC27: 4 | AD27: Owned | AE27: 14 | AF27: 0 | AG27: =J27+AF27 -> 1759454 | AH27: 1 | AI27: N | AJ27: 300 | AK27: =(IF(S27="Credit Card",0.36,IF(S27="Personal Loan",0.14,IF(S27="Car Loan",0.09,0.085))))+IF(Z27="Low",0,IF(Z27="Medium",0.015,0.03)) -> 0.085 | AL27: =-PMT(AK27/12,AJ27,T27) -> 0 | AM27: =IFERROR(T27/J27,0) -> 0 | AN27: =R27+AL27 -> 24409.74 | AO27: =IFERROR((AN27*12)/J27,0) -> 0.16648169 | AP27: 9168240 | AQ27: =IF(AP27>0,T27/AP27,"N/A") -> 0 | AR27: 46160 | AS27: Verified
A28: CUST00027 | B28: Anil Joshi | C28: 9771527524 | D28: anil.joshi453@gmail.com | E28: 34 | F28: Female | G28: Coimbatore | H28: Self Employed - Business | I28: Self-Employed | J28: 1508081 | K28: 2 | L28: Y | M28: N | N28: Y | O28: N | P28: 545 | Q28: 642246 | R28: 20717.61 | S28: Credit Card | T28: 309538 | U28: =IFERROR((R28*12)/J28,0) -> 0.16485276 | V28: 0 | W28: 26.3 | X28: 12.7 | Y28: =ROUND(0.4*((900-P28)/600*100)+0.3*MIN(U28*100,100)+0.2*MIN(V28*20,100)+0.1*W28,1) -> 31.2 | Z28: =IF(Y28<=30,"Low",IF(Y28<=60,"Medium","High")) -> Medium | AA28: =IF(AND(P28>=650,U28<=0.4,V28<=2,Y28<=50),"Eligible",IF(AND(P28>=550,V28<=4,Y28<=75),"Review","Not Eligible")) -> Not Eligible | AB28: Married | AC28: 3 | AD28: Rented | AE28: 2.3 | AF28: 0 | AG28: =J28+AF28 -> 1508081 | AH28: 0 | AI28: N | AJ28: 36 | AK28: =(IF(S28="Credit Card",0.36,IF(S28="Personal Loan",0.14,IF(S28="Car Loan",0.09,0.085))))+IF(Z28="Low",0,IF(Z28="Medium",0.015,0.03)) -> 0.375 | AL28: =-PMT(AK28/12,AJ28,T28) -> 14443.691 | AM28: =IFERROR(T28/J28,0) -> 0.2052529 | AN28: =R28+AL28 -> 35161.301 | AO28: =IFERROR((AN28*12)/J28,0) -> 0.27978312 | AP28: 0 | AQ28: =IF(AP28>0,T28/AP28,"N/A") -> N/A | AR28: 46142 | AS28: Pending
A29: CUST00028 | B29: Rahul Kapoor | C29: 9691916368 | E29: 33 | F29: Male | G29: Bengaluru | H29: Salaried - IT/Tech | I29: Salaried | J29: 2040394 | K29: 2 | L29: Y | M29: N | N29: N | O29: Y | P29: 605 | Q29: 1025268.5 | R29: 20923.85 | S29: Home Loan | U29: =IFERROR((R29*12)/J29,0) -> 0.1230577 | V29: 0 | W29: 51 | X29: 5.1 | Y29: =ROUND(0.4*((900-P29)/600*100)+0.3*MIN(U29*100,100)+0.2*MIN(V29*20,100)+0.1*W29,1) -> 28.5 | Z29: =IF(Y29<=30,"Low",IF(Y29<=60,"Medium","High")) -> Low | AA29: =IF(AND(P29>=650,U29<=0.4,V29<=2,Y29<=50),"Eligible",IF(AND(P29>=550,V29<=4,Y29<=75),"Review","Not Eligible")) -> Review | AB29: Single | AC29: 1 | AD29: Company Provided | AE29: 10.5 | AF29: 0 | AG29: =J29+AF29 -> 2040394 | AH29: 0 | AI29: N | AJ29: 300 | AK29: =(IF(S29="Credit Card",0.36,IF(S29="Personal Loan",0.14,IF(S29="Car Loan",0.09,0.085))))+IF(Z29="Low",0,IF(Z29="Medium",0.015,0.03)) -> 0.085 | AL29: =-PMT(AK29/12,AJ29,T29) -> 0 | AM29: =IFERROR(T29/J29,0) -> 0 | AN29: =R29+AL29 -> 20923.85 | AO29: =IFERROR((AN29*12)/J29,0) -> 0.1230577 | AP29: 3188454 | AQ29: =IF(AP29>0,T29/AP29,"N/A") -> 0 | AR29: 46137 | AS29: Verified
A30: CUST00029 | B30: Preeti Chopra | C30: 9514548900 | D30: preeti.chopra680@yahoo.com | E30: 52 | F30: Male | G30: Chennai | H30: Freelancer | I30: Self-Employed | J30: 1692486 | K30: 0 | L30: N | M30: N | N30: N | O30: N | P30: 767 | Q30: 2597.56 | R30: 123.69 | S30: Home Loan | T30: 6992703 | U30: =IFERROR((R30*12)/J30,0) -> 0.00087698214 | V30: 6 | W30: 12.1 | X30: 11.8 | Y30: =ROUND(0.4*((900-P30)/600*100)+0.3*MIN(U30*100,100)+0.2*MIN(V30*20,100)+0.1*W30,1) -> 30.1 | Z30: =IF(Y30<=30,"Low",IF(Y30<=60,"Medium","High")) -> Medium | AA30: =IF(AND(P30>=650,U30<=0.4,V30<=2,Y30<=50),"Eligible",IF(AND(P30>=550,V30<=4,Y30<=75),"Review","Not Eligible")) -> Not Eligible | AB30: Married | AC30: 2 | AD30: Owned | AE30: 2.7 | AF30: 655768 | AG30: =J30+AF30 -> 2348254 | AH30: 0 | AI30: Y | AJ30: 300 | AK30: =(IF(S30="Credit Card",0.36,IF(S30="Personal Loan",0.14,IF(S30="Car Loan",0.09,0.085))))+IF(Z30="Low",0,IF(Z30="Medium",0.015,0.03)) -> 0.1 | AL30: =-PMT(AK30/12,AJ30,T30) -> 63542.744 | AM30: =IFERROR(T30/J30,0) -> 4.1316165 | AN30: =R30+AL30 -> 63666.434 | AO30: =IFERROR((AN30*12)/J30,0) -> 0.45140534 | AP30: 9566687 | AQ30: =IF(AP30>0,T30/AP30,"N/A") -> 0.73094301 | AR30: 45913 | AS30: Verified
A31: CUST00030 | B31: Rahul Mishra | D31: rahul.mishra944@outlook.com | E31: 35 | F31: Male | G31: Indore | H31: Salaried - Government | I31: Salaried | J31: 721557 | K31: 2 | L31: Y | M31: N | N31: N | O31: Y | P31: 357 | R31: 3628.83 | S31: Home Loan | T31: 2721127 | U31: =IFERROR((R31*12)/J31,0) -> 0.060349993 | V31: 0 | W31: 44.1 | X31: 10.3 | Y31: =ROUND(0.4*((900-P31)/600*100)+0.3*MIN(U31*100,100)+0.2*MIN(V31*20,100)+0.1*W31,1) -> 42.4 | Z31: =IF(Y31<=30,"Low",IF(Y31<=60,"Medium","High")) -> Medium | AA31: =IF(AND(P31>=650,U31<=0.4,V31<=2,Y31<=50),"Eligible",IF(AND(P31>=550,V31<=4,Y31<=75),"Review","Not Eligible")) -> Not Eligible | AB31: Married | AC31: 0 | AD31: Rented | AE31: 5.5 | AF31: 0 | AG31: =J31+AF31 -> 721557 | AH31: 0 | AI31: N | AJ31: 180 | AK31: =(IF(S31="Credit Card",0.36,IF(S31="Personal Loan",0.14,IF(S31="Car Loan",0.09,0.085))))+IF(Z31="Low",0,IF(Z31="Medium",0.015,0.03)) -> 0.1 | AL31: =-PMT(AK31/12,AJ31,T31) -> 29241.37 | AM31: =IFERROR(T31/J31,0) -> 3.7711879 | AN31: =R31+AL31 -> 32870.2 | AO31: =IFERROR((AN31*12)/J31,0) -> 0.54665453 | AP31: 3443008 | AQ31: =IF(AP31>0,T31/AP31,"N/A") -> 0.79033421 | AR31: 46025 | AS31: Verified
A32: CUST00031 | B32: Mahesh Sharma | C32: 9963968184 | E32: 64 | F32: Male | G32: Bengaluru | H32: Business Owner | I32: Self-Employed | J32: 1749407 | K32: 1 | L32: N | M32: Y | N32: N | O32: N | P32: 767 | Q32: 887268.36 | R32: 36969.51 | S32: Home Loan | U32: =IFERROR((R32*12)/J32,0) -> 0.25359114 | V32: 0 | W32: 41.2 | X32: 5.5 | Y32: =ROUND(0.4*((900-P32)/600*100)+0.3*MIN(U32*100,100)+0.2*MIN(V32*20,100)+0.1*W32,1) -> 20.6 | Z32: =IF(Y32<=30,"Low",IF(Y32<=60,"Medium","High")) -> Low | AA32: =IF(AND(P32>=650,U32<=0.4,V32<=2,Y32<=50),"Eligible",IF(AND(P32>=550,V32<=4,Y32<=75),"Review","Not Eligible")) -> Eligible | AB32: Married | AC32: 2 | AD32: Owned | AE32: 25 | AF32: 0 | AG32: =J32+AF32 -> 1749407 | AH32: 0 | AI32: N | AJ32: 120 | AK32: =(IF(S32="Credit Card",0.36,IF(S32="Personal Loan",0.14,IF(S32="Car Loan",0.09,0.085))))+IF(Z32="Low",0,IF(Z32="Medium",0.015,0.03)) -> 0.085 | AL32: =-PMT(AK32/12,AJ32,T32) -> 0 | AM32: =IFERROR(T32/J32,0) -> 0 | AN32: =R32+AL32 -> 36969.51 | AO32: =IFERROR((AN32*12)/J32,0) -> 0.25359114 | AP32: 7650724 | AQ32: =IF(AP32>0,T32/AP32,"N/A") -> 0 | AR32: 46149 | AS32: Verified
A33: CUST00032 | B33: Lata Iyer | C33: 9932945529 | D33: lata.iyer819@yahoo.com | E33: 59 | F33: Female | G33: Ahmedabad | H33: Self Employed - Professional | I33: Self-Employed | J33: 1351204 | K33: 0 | L33: N | M33: N | N33: N | O33: N | P33: 399 | Q33: 122068 | R33: 2303.17 | S33: Credit Card | T33: 181969 | U33: =IFERROR((R33*12)/J33,0) -> 0.02045438 | V33: 3 | W33: 8.2 | X33: 5.6 | Y33: =ROUND(0.4*((900-P33)/600*100)+0.3*MIN(U33*100,100)+0.2*MIN(V33*20,100)+0.1*W33,1) -> 46.8 | Z33: =IF(Y33<=30,"Low",IF(Y33<=60,"Medium","High")) -> Medium | AA33: =IF(AND(P33>=650,U33<=0.4,V33<=2,Y33<=50),"Eligible",IF(AND(P33>=550,V33<=4,Y33<=75),"Review","Not Eligible")) -> Not Eligible | AB33: Married | AC33: 3 | AD33: Owned | AE33: 12.6 | AF33: 739885 | AG33: =J33+AF33 -> 2091089 | AH33: 2 | AI33: N | AJ33: 24 | AK33: =(IF(S33="Credit Card",0.36,IF(S33="Personal Loan",0.14,IF(S33="Car Loan",0.09,0.085))))+IF(Z33="Low",0,IF(Z33="Medium",0.015,0.03)) -> 0.375 | AL33: =-PMT(AK33/12,AJ33,T33) -> 10889.997 | AM33: =IFERROR(T33/J33,0) -> 0.13467174 | AN33: =R33+AL33 -> 13193.167 | AO33: =IFERROR((AN33*12)/J33,0) -> 0.1171681 | AP33: 0 | AQ33: =IF(AP33>0,T33/AP33,"N/A") -> N/A | AR33: 45979 | AS33: Verified
A34: CUST00033 | B34: Geeta Joshi | C34: 9965960427 | D34: geeta.joshi303@outlook.com | E34: 28 | F34: Female | G34: Bengaluru | H34: Self Employed - Business | I34: Self-Employed | J34: 1246296 | K34: 0 | L34: N | M34: N | N34: N | O34: N | P34: 870 | Q34: 45586.4 | R34: 1232.06 | S34: Credit Card | T34: 158652 | U34: =IFERROR((R34*12)/J34,0) -> 0.011862928 | V34: 1 | W34: 48.2 | X34: 10.2 | Y34: =ROUND(0.4*((900-P34)/600*100)+0.3*MIN(U34*100,100)+0.2*MIN(V34*20,100)+0.1*W34,1) -> 11.2 | Z34: =IF(Y34<=30,"Low",IF(Y34<=60,"Medium","High")) -> Low | AA34: =IF(AND(P34>=650,U34<=0.4,V34<=2,Y34<=50),"Eligible",IF(AND(P34>=550,V34<=4,Y34<=75),"Review","Not Eligible")) -> Eligible | AB34: Single | AC34: 2 | AD34: Rented | AE34: 6.6 | AF34: 325366 | AG34: =J34+AF34 -> 1571662 | AH34: 0 | AI34: Y | AJ34: 24 | AK34: =(IF(S34="Credit Card",0.36,IF(S34="Personal Loan",0.14,IF(S34="Car Loan",0.09,0.085))))+IF(Z34="Low",0,IF(Z34="Medium",0.015,0.03)) -> 0.36 | AL34: =-PMT(AK34/12,AJ34,T34) -> 9367.9906 | AM34: =IFERROR(T34/J34,0) -> 0.12729881 | AN34: =R34+AL34 -> 10600.051 | AO34: =IFERROR((AN34*12)/J34,0) -> 0.10206292 | AP34: 0 | AQ34: =IF(AP34>0,T34/AP34,"N/A") -> N/A | AR34: 46207 | AS34: Verified
A35: CUST00034 | B35: Arjun Mishra | D35: arjun.mishra476@outlook.com | E35: 62 | F35: Female | G35: Hyderabad | H35: Self Employed - Business | I35: Self-Employed | J35: 490198 | K35: 1 | L35: N | M35: N | N35: N | O35: Y | P35: 850 | Q35: 39901 | R35: 973.2 | S35: Car Loan | T35: 1432865 | U35: =IFERROR((R35*12)/J35,0) -> 0.023823843 | V35: 0 | W35: 75.5 | X35: 2.5 | Y35: =ROUND(0.4*((900-P35)/600*100)+0.3*MIN(U35*100,100)+0.2*MIN(V35*20,100)+0.1*W35,1) -> 11.6 | Z35: =IF(Y35<=30,"Low",IF(Y35<=60,"Medium","High")) -> Low | AA35: =IF(AND(P35>=650,U35<=0.4,V35<=2,Y35<=50),"Eligible",IF(AND(P35>=550,V35<=4,Y35<=75),"Review","Not Eligible")) -> Eligible | AB35: Married | AC35: 0 | AD35: Rented | AE35: 12.4 | AF35: 0 | AG35: =J35+AF35 -> 490198 | AH35: 0 | AI35: N | AJ35: 60 | AK35: =(IF(S35="Credit Card",0.36,IF(S35="Personal Loan",0.14,IF(S35="Car Loan",0.09,0.085))))+IF(Z35="Low",0,IF(Z35="Medium",0.015,0.03)) -> 0.09 | AL35: =-PMT(AK35/12,AJ35,T35) -> 29743.921 | AM35: =IFERROR(T35/J35,0) -> 2.9230331 | AN35: =R35+AL35 -> 30717.121 | AO35: =IFERROR((AN35*12)/J35,0) -> 0.75195217 | AP35: 1631946 | AQ35: =IF(AP35>0,T35/AP35,"N/A") -> 0.87801006 | AR35: 46015 | AS35: Verified
A36: CUST00035 | B36: Reyansh Pandey | E36: 24 | F36: Female | G36: Jaipur | H36: Self Employed - Professional | I36: Self-Employed | J36: 812374 | K36: 1 | L36: N | M36: N | N36: Y | O36: N | P36: 321 | Q36: 24653.2 | R36: 747.07 | S36: Personal Loan | T36: 182040 | U36: =IFERROR((R36*12)/J36,0) -> 0.011035361 | V36: 3 | W36: 24.5 | X36: 12.5 | Y36: =ROUND(0.4*((900-P36)/600*100)+0.3*MIN(U36*100,100)+0.2*MIN(V36*20,100)+0.1*W36,1) -> 53.4 | Z36: =IF(Y36<=30,"Low",IF(Y36<=60,"Medium","High")) -> Medium | AA36: =IF(AND(P36>=650,U36<=0.4,V36<=2,Y36<=50),"Eligible",IF(AND(P36>=550,V36<=4,Y36<=75),"Review","Not Eligible")) -> Not Eligible | AB36: Married | AC36: 2 | AD36: Rented | AE36: 0.9 | AF36: 0 | AG36: =J36+AF36 -> 812374 | AH36: 1 | AI36: N | AJ36: 36 | AK36: =(IF(S36="Credit Card",0.36,IF(S36="Personal Loan",0.14,IF(S36="Car Loan",0.09,0.085))))+IF(Z36="Low",0,IF(Z36="Medium",0.015,0.03)) -> 0.155 | AL36: =-PMT(AK36/12,AJ36,T36) -> 6355.1404 | AM36: =IFERROR(T36/J36,0) -> 0.22408398 | AN36: =R36+AL36 -> 7102.2104 | AO36: =IFERROR((AN36*12)/J36,0) -> 0.10491045 | AP36: 0 | AQ36: =IF(AP36>0,T36/AP36,"N/A") -> N/A | AR36: 45969 | AS36: Pending
A37: CUST00036 | B37: Shreya Nair | C37: 9957397689 | D37: shreya.nair179@gmail.com | E37: 63 | F37: Male | G37: Chennai | H37: Salaried - Private | I37: Salaried | J37: 1802577 | K37: 2 | L37: N | M37: Y | N37: N | O37: Y | P37: 353 | R37: 3607.77 | S37: Credit Card | U37: =IFERROR((R37*12)/J37,0) -> 0.024017415 | V37: 0 | W37: 47.6 | X37: 5.6 | Y37: =ROUND(0.4*((900-P37)/600*100)+0.3*MIN(U37*100,100)+0.2*MIN(V37*20,100)+0.1*W37,1) -> 41.9 | Z37: =IF(Y37<=30,"Low",IF(Y37<=60,"Medium","High")) -> Medium | AA37: =IF(AND(P37>=650,U37<=0.4,V37<=2,Y37<=50),"Eligible",IF(AND(P37>=550,V37<=4,Y37<=75),"Review","Not Eligible")) -> Not Eligible | AB37: Married | AC37: 1 | AD37: Owned | AE37: 18.6 | AF37: 0 | AG37: =J37+AF37 -> 1802577 | AH37: 2 | AI37: N | AJ37: 24 | AK37: =(IF(S37="Credit Card",0.36,IF(S37="Personal Loan",0.14,IF(S37="Car Loan",0.09,0.085))))+IF(Z37="Low",0,IF(Z37="Medium",0.015,0.03)) -> 0.375 | AL37: =-PMT(AK37/12,AJ37,T37) -> 0 | AM37: =IFERROR(T37/J37,0) -> 0 | AN37: =R37+AL37 -> 3607.77 | AO37: =IFERROR((AN37*12)/J37,0) -> 0.024017415 | AP37: 0 | AQ37: =IF(AP37>0,T37/AP37,"N/A") -> N/A | AR37: 46129 | AS37: Verified
A38: CUST00037 | B38: Vivaan Verma | C38: 9614302907 | D38: vivaan.verma868@hotmail.com | E38: 48 | F38: Male | G38: Chandigarh | H38: Business Owner | I38: Self-Employed | J38: 608242 | K38: 2 | L38: N | M38: N | N38: Y | O38: Y | P38: 899 | Q38: 200120 | R38: 6253.75 | S38: Home Loan | U38: =IFERROR((R38*12)/J38,0) -> 0.12338017 | V38: 1 | W38: 48.1 | X38: 9.2 | Y38: =ROUND(0.4*((900-P38)/600*100)+0.3*MIN(U38*100,100)+0.2*MIN(V38*20,100)+0.1*W38,1) -> 12.6 | Z38: =IF(Y38<=30,"Low",IF(Y38<=60,"Medium","High")) -> Low | AA38: =IF(AND(P38>=650,U38<=0.4,V38<=2,Y38<=50),"Eligible",IF(AND(P38>=550,V38<=4,Y38<=75),"Review","Not Eligible")) -> Eligible | AB38: Married | AC38: 2 | AD38: Rented | AE38: 17.7 | AF38: 0 | AG38: =J38+AF38 -> 608242 | AH38: 1 | AI38: N | AJ38: 300 | AK38: =(IF(S38="Credit Card",0.36,IF(S38="Personal Loan",0.14,IF(S38="Car Loan",0.09,0.085))))+IF(Z38="Low",0,IF(Z38="Medium",0.015,0.03)) -> 0.085 | AL38: =-PMT(AK38/12,AJ38,T38) -> 0 | AM38: =IFERROR(T38/J38,0) -> 0 | AN38: =R38+AL38 -> 6253.75 | AO38: =IFERROR((AN38*12)/J38,0) -> 0.12338017 | AP38: 8933633 | AQ38: =IF(AP38>0,T38/AP38,"N/A") -> 0 | AR38: 46106 | AS38: Verified
A39: CUST00038 | B39: Neha Chopra | C39: 9546665485 | D39: neha.chopra748@gmail.com | E39: 41 | F39: Female | G39: Lucknow | H39: Salaried - IT/Tech | I39: Salaried | J39: 1869932 | K39: 1 | L39: N | M39: N | N39: N | O39: Y | P39: 387 | Q39: 104600 | R39: 5811.13 | S39: Car Loan | T39: 572871 | U39: =IFERROR((R39*12)/J39,0) -> 0.03729203 | V39: 1 | W39: 60.7 | X39: 8.5 | Y39: =ROUND(0.4*((900-P39)/600*100)+0.3*MIN(U39*100,100)+0.2*MIN(V39*20,100)+0.1*W39,1) -> 45.4 | Z39: =IF(Y39<=30,"Low",IF(Y39<=60,"Medium","High")) -> Medium | AA39: =IF(AND(P39>=650,U39<=0.4,V39<=2,Y39<=50),"Eligible",IF(AND(P39>=550,V39<=4,Y39<=75),"Review","Not Eligible")) -> Not Eligible | AB39: Married | AC39: 0 | AD39: Owned | AE39: 13.4 | AF39: 0 | AG39: =J39+AF39 -> 1869932 | AH39: 2 | AI39: N | AJ39: 48 | AK39: =(IF(S39="Credit Card",0.36,IF(S39="Personal Loan",0.14,IF(S39="Car Loan",0.09,0.085))))+IF(Z39="Low",0,IF(Z39="Medium",0.015,0.03)) -> 0.105 | AL39: =-PMT(AK39/12,AJ39,T39) -> 14667.434 | AM39: =IFERROR(T39/J39,0) -> 0.30635927 | AN39: =R39+AL39 -> 20478.564 | AO39: =IFERROR((AN39*12)/J39,0) -> 0.13141802 | AP39: 670306 | AQ39: =IF(AP39>0,T39/AP39,"N/A") -> 0.85464101 | AR39: 46075 | AS39: Verified
A40: CUST00039 | B40: Sneha Reddy | C40: 9266140258 | E40: 35 | F40: Male | G40: Kanpur | H40: Freelancer | I40: Self-Employed | J40: 1841662 | K40: 3 | L40: Y | M40: Y | N40: Y | O40: N | P40: 874 | R40: 21115.12 | S40: Credit Card | T40: 339288 | U40: =IFERROR((R40*12)/J40,0) -> 0.13758303 | V40: 5 | W40: 83.8 | X40: 4.2 | Y40: =ROUND(0.4*((900-P40)/600*100)+0.3*MIN(U40*100,100)+0.2*MIN(V40*20,100)+0.1*W40,1) -> 34.2 | Z40: =IF(Y40<=30,"Low",IF(Y40<=60,"Medium","High")) -> Medium | AA40: =IF(AND(P40>=650,U40<=0.4,V40<=2,Y40<=50),"Eligible",IF(AND(P40>=550,V40<=4,Y40<=75),"Review","Not Eligible")) -> Not Eligible | AB40: Married | AC40: 2 | AD40: Owned | AE40: 5 | AF40: 802397 | AG40: =J40+AF40 -> 2644059 | AH40: 1 | AI40: N | AJ40: 18 | AK40: =(IF(S40="Credit Card",0.36,IF(S40="Personal Loan",0.14,IF(S40="Car Loan",0.09,0.085))))+IF(Z40="Low",0,IF(Z40="Medium",0.015,0.03)) -> 0.375 | AL40: =-PMT(AK40/12,AJ40,T40) -> 24930.631 | AM40: =IFERROR(T40/J40,0) -> 0.18422925 | AN40: =R40+AL40 -> 46045.751 | AO40: =IFERROR((AN40*12)/J40,0) -> 0.30002737 | AP40: 0 | AQ40: =IF(AP40>0,T40/AP40,"N/A") -> N/A | AR40: 46219 | AS40: Pending
...

Sheet Raw Data (Unclean)
A1: Customer ID | B1: Full Name | C1: Phone Number | D1: Email ID | E1: Age | F1: Gender | G1: City | H1: Occupation | I1: Employment Type | J1: Annual Income | K1: Existing Products Count | L1: Has Credit Card | M1: Has Personal Loan | N1: Has Car Loan | O1: Has Home Loan | P1: Credit Score | Q1: Existing Outstanding Debt | R1: Monthly EMI Outstanding | S1: Requested Loan Type | T1: Requested Amount | U1: Missed Payments (12M) | V1: Credit Utilization (%) | W1: Years with Bank | X1: Marital Status | Y1: Number of Dependents | Z1: Residence Type | AA1: Employment Tenure (Years) | AB1: Co-Applicant Income | AC1: Existing Loans (Other Banks) | AD1: Previous Default History | AE1: Requested Tenure (Months) | AF1: Collateral Value | AG1: Application Date | AH1: KYC Status
A2: CUST00001 | B2: Rajesh Kumar | D2: rajesh.kumar760@outlook.com | E2: 36 | F2: MALE | G2: Chennai | H2: SALARIED - GOVERNMENT | I2: Salaried | J2: 664,647 | K2: 2 | L2: 0 | M2: Y | N2: Yes | O2: false | P2: 327 | Q2: 223817.91 | R2: 3926.63 | S2: Home Loan | T2: ₹3,349,189 | U2: 0 | V2: 31.4 | W2: 13.1 | X2: Single | Y2: 0 | Z2: Owned | AA2: 4.4 | AB2: 722621.0 | AC2: 0 | AD2: NO | AE2: 240 | AF2: 4561172.0 | AG2: 2026/07/01 | AH2: Verified
A3: CUST00002 | B3: Aditya Yadav | C3: 95933037 | D3: aditya.yadav550@gmail.com | E3: 45 | F3: MALE | G3: Coimbatore | H3: Salaried - IT/Tech | I3: Salaried | J3: 1,816,807 | K3: 1 | L3: NO | M3: no | N3: 1 | O3: no | P3: 596 | Q3: ₹1,073,974 | R3: 41306.71 | S3: Credit Card | T3: 219295 | U3: 0 | V3: 65.4 | W3: 5.6 | X3: married | Y3: 0 | Z3: Owned | AA3: 22.5 | AC3: 1 | AD3: NO | AE3: 18 | AH3: Verified
A4: CUST00003 | B4: Vikram Khanna | D4: vikram.khanna705@rediffmail.com | E4: 35 | F4: Female | G4: delhi | H4: Self Employed - Professional | I4: Self-Employed | J4: 434638 | K4: 1 | L4: NO | M4: false | N4: YES | O4: 0 | P4: 880 | Q4: 228541.6 | R4: 7141.93 | S4: PERSONAL LOAN | T4: ₹737,277 | U4: 1 | V4: 89.0 | W4: 9.7 | X4: Married | Y4: 0 | Z4: Rented | AA4: 7.7 | AC4: 0 | AD4: NO | AE4: 36 | AG4: 16 Dec 2025 | AH4: Pending
A5: CUST00004 | B5: Krishna Desai | C5: 09629908599 | D5: krishna.desai94 at gmail.com | E5: 28 | F5: Male | G5: Calcutta | H5: Salaried - Education | I5: Salaried | J5: 566454 | K5: 1 | L5: yes | M5: no | N5: no | O5: N | P5: 866 | Q5: 292,555 | R5: 24379.6 | S5: Credit Card | U5: 4 | V5: 76.3 | W5: 11.6 | X5: Married | Y5: 1 | Z5: Owned | AA5: 0.3 | AC5: 1 | AD5: true | AE5: 18 | AG5: 2026/05/12 | AH5: Verified
A6: CUST00005 | B6: Usha Mishra | C6: +91-9420452650 | D6: USHA.MISHRA862@REDIFFMAIL.COM | E6: 59 | F6: M | G6: Chennai | H6: Salaried - Healthcare | I6: Salaried | J6: 977,585 | K6: 2 | L6: 1 | M6: 0 | N6: NO | O6: Yes | P6: 631 | Q6: 286,592 | R6: 15083.8 | S6: Car Loan | T6: -944903 | U6: 0 | V6: 27.9 | W6: 8.6 | X6: Married | Y6: 2 | Z6: Rented | AA6: 29.3 | AC6: 0 | AD6: false | AE6: 72 | AF6: 1023354.0 | AG6: 2026-05-23 | AH6: Verified
A7: CUST00006 | B7: Saanvi Reddy | E7: 40 | F7: FEMALE | G7: KANPUR | H7: Business Owner | I7: Self-Employed | K7: 4 | L7: YES | M7: 1 | N7: Y | O7: Y | P7: 867 | Q7: N/A | R7: 13121.16 | S7: credit card | T7: ₹57,220 | U7: 2 | V7: 10.6 | W7: 1.2 | X7: Married | Y7: 1 | Z7: Rented | AA7: 5.5 | AC7: 0 | AD7: no | AE7: 36 | AG7: 2025/12/28 | AH7: Verified
A8: CUST00007 | B8: Preeti Malhotra | C8: 9304451095 | D8: preeti.malhotra97@gmail,com | E8: 63 | F8: female | G8: Kanpur | H8: Salaried - Education | I8: Salaried | J8: 2024287 | K8: 1 | L8: 1 | M8: NO | N8: false | O8: N | P8: 400 | Q8: ₹73,618 | R8: 1269.28 | S8: Car Loan | U8: 0 | V8: 23.1 | W8: 6.8 | X8: Married | Y8: 1 | Z8: Owned | AA8: 27.7 | AC8: 2 | AD8: 0 | AE8: 24 | AF8: 624628.0 | AG8: 05/29/2026 | AH8: Verified
A9: CUST00008 | B9: Sai Khanna | C9: 09909134796 | D9: sai.khanna870@yahoo.com | E9: 31 | F9: Female | G9: Chandigarh | H9: BUSINESS OWNER | I9: Self-Employed | J9: ₹1,196,521 | K9: 2 | L9: NO | M9: No | N9: true | O9: 1 | P9: 699 | Q9: 190,393 | R9: 4643.72 | S9: Car Loan | T9: 1187110 | U9: 2 | V9: 74.4 | W9: 11.8 | X9: Single | Y9: 1 | Z9: Owned | AA9: 2.4 | AB9: 701803.0 | AC9: 0 | AD9: No | AE9: 24 | AF9: 1385162.0 | AG9: 10-05-2026 | AH9: Verified
A10: CUST00009 | B10: Divya Patel | C10: 9161073976 | D10: divya.patel984@rediffmail.com | E10: 26 | F10: Male | G10: BENGALURU | H10: Salaried - Government | I10: Salaried | J10: 1,286,516 | K10: 1 | L10: Yes | M10: no | N10: false | O10: NO | P10: 340 | Q10: 478106.53 | R10: 12581.75 | S10: Car Loan | T10: 846,865 | U10: 0 | V10: 73.0 | W10: 3.7 | X10: Married | Y10: 2 | Z10: OWNED | AA10: 1.8 | AC10: 0 | AD10: No | AE10: 72 | AF10: 1057920.0 | AG10: 02-10-2025 | AH10: Verified
A11: CUST00010 | B11: Sneha Nair | C11: 09242224154 | E11: 25 | F11: Male | G11: Kanpur | H11: Salaried - IT/Tech | I11: Salaried | J11: 961638 | K11: 1 | L11: Y | M11: 0 | N11: false | O11: No | P11: 841 | Q11: 4513.8 | R11: 96.04 | S11: Car Loan | T11: ₹517,236 | U11: 5 | V11: 17.8 | W11: 1.9 | X11: Married | Y11: 2 | Z11: Owned | AA11: 2.5 | AC11: 0 | AD11: No | AE11: 48 | AF11: 595381.0 | AG11: 2026-01-01 | AH11: Verified
A12: CUST00011 | B12: Rekha Verma | C12: 9199104722 | D12: rekha.verma650@hotmail.com | E12: 38 | F12: F | G12: Mumbai | H12: Salaried - Healthcare | I12: Salaried | K12: 1 | L12: 0 | M12: Y | N12: no | O12: No | P12: 737 | Q12: 285623.98 | R12: 15032.84 | S12: CREDIT CARD | T12: N/A | U12: 2 | V12: 19.2 | W12: 0.7 | X12: MARRIED | Y12: 2 | Z12: Owned | AA12: 1.0 | AC12: 3 | AD12: 1 | AE12: 12 | AG12: 2026/02/25 | AH12: Verified
A13: CUST00012 | B13: Rahul Pandey | D13: rahul.pandey363@rediffmail.com | E13: 47 | F13: F | G13: AHMEDABAD | H13: Self Employed - Business | I13: Self-Employed | J13: N/A | K13: 1 | L13: No | M13: true | N13: NO | O13: no | P13: 721 | Q13: 501851.51 | R13: 8505.96 | S13: Personal Loan | T13: ₹329,766 | U13: 0 | V13: 71.6 | W13: 5.9 | X13: Married | Y13: 1 | Z13: Owned | AA13: 23.9 | AB13: 765402.0 | AC13: 2 | AD13: NO | AE13: 24 | AG13: 2026-03-18 | AH13: Verified
A14: CUST00013 | B14: Usha Gupta | C14: +91-9930353157 | D14: usha.gupta286@outlook.com | E14: 62 | F14: female | G14: Coimbatore | H14: Salaried - Healthcare | I14: Salaried | J14: 415765 | K14: 2 | L14: true | M14: false | N14: true | O14: NO | P14: 571 | Q14: 9543.6 | R14: 190.87 | S14: Home Loan | T14: ₹4,399,833 | U14: 2 | V14: 34.8 | W14: 9.2 | X14: Married | Y14: 1 | Z14: Rented | AA14: 7.9 | AC14: 0 | AD14: yes | AE14: 360 | AF14: 5815322.0 | AG14: 04-08-2026 | AH14: Verified
A15: CUST00014 | B15: saanvi gupta | C15: 98132 19781 | D15: saanvi.gupta943@outlook.com | E15: 60 | F15: female | G15: Hyderabad | H15: Salaried - IT/Tech | I15: Salaried | J15: ₹2,427,025 | K15: 1 | L15: 1 | M15: 0 | N15: NO | O15: 0 | P15: 430 | R15: 5173.34 | S15: Home Loan | T15: ₹7,181,754 | U15: 2 | V15: 21.5 | W15: 8.6 | X15: Married | Y15: 3 | Z15: owned | AA15: 6.5 | AC15: 1 | AD15: No | AE15: 300 | AF15: 9052888.0 | AG15: 12/13/2025 | AH15: verified
A16: CUST00015 | B16: Kiran Sethi | C16: 99547 25078 | D16: KIRAN.SETHI754@YAHOO.COM | E16: 63 | F16: M | G16: Surat | H16: Freelancer | I16: Self-Employed | K16: 2 | L16: Y | M16: NO | N16: Y | O16: false | P16: 503 | Q16: ₹150,821 | R16: 10772.93 | S16: Personal Loan | T16: ₹548,216 | U16: 1 | V16: 78.0 | W16: 6.9 | X16: Single | Y16: 2 | Z16: RENTED | AA16: 11.7 | AC16: 0 | AD16: 0 | AE16: 12 | AG16: 2026/03/31 | AH16: Verified
A17: CUST00016 | B17: Preeti Tiwari | C17: 9656152900 | D17: preeti.tiwari476@gmail.com | E17: 56 | F17: Male | G17: Hyderabad | H17: Business Owner | I17: Self-Employed | J17: ₹859,264 | K17: 0 | L17: no | M17: 0 | N17: false | O17: No | P17: 753 | Q17: 52643.01 | R17: 907.64 | S17: Home Loan | U17: 0 | V17: 20.1 | W17: 13.0 | X17: Married | Y17: 2 | Z17: Rented | AA17: 8.5 | AC17: 0 | AD17: 0 | AE17: 300 | AF17: 7128348.0 | AG17: 2026/01/19 | AH17: Verified
A18: CUST00017 | B18: Diya Mehta | C18: 9679984033 | D18: diya.mehta83@yahoo.com | E18: 30 | F18: male | G18: Nagpur | H18: Self Employed - Business | I18: Self-Employed | J18: 1197383 | K18: 1 | L18: true | M18: false | N18: false | O18: No | P18: 511 | Q18: ₹598,374 | R18: 16621.5 | S18: CREDIT CARD | U18: 4 | V18: 59.7 | W18: 7.3 | X18: Single | Y18: 1 | Z18: Owned | AA18: 8.1 | AC18: 0 | AD18: No | AE18: 18 | AG18: 02-05-2026 | AH18: Verified
A19: CUST00018 | B19: saanvi joshi | C19: 91311 65166 | D19: saanvi.joshi399@outlook.com | E19: 63 | F19: Female | G19: KOLKATA | H19: Business Owner | I19: Self-Employed | K19: 0 | L19: NO | M19: No | N19: NO | O19: No | Q19: ₹7,012 | R19: 179.8 | S19: Personal Loan | T19: 958,959 | U19: 1 | V19: 9.8 | W19: 5.8 | X19: Married | Y19: 1 | Z19: Rented | AA19: 11.6 | AC19: 2 | AD19: N | AE19: 12 | AG19: 23-04-2026 | AH19: Verified
A20: CUST00019 | B20: Shreya Verma | C20: 9475767056 | D20: shreya.verma230@gmail.com | E20: 62 | F20: male | G20: Mumbai | H20: Self Employed - Professional | I20: Self-Employed | J20: 1136179 | K20: 1 | L20: false | M20: no | N20: Yes | O20: NO | P20: 417 | Q20: -384462.24 | R20: 15378.49 | S20: Home Loan | T20: 7367537 | U20: 0 | V20: 40.0 | W20: 9.2 | X20: Divorced | Y20: 2 | Z20: Rented | AA20: 5.2 | AB20: 584014.0 | AC20: 2 | AD20: 0 | AE20: 300 | AF20: 9203259.0 | AG20: 05-12-2025 | AH20: Verified
A21: CUST00020 | B21: Deepak Saxena | C21: 9773496394 | D21: DEEPAK.SAXENA249@GMAIL.COM | E21: 65 | F21: Female | G21: Hyderabad | H21: SALARIED - PRIVATE | I21: Salaried | J21: ₹1,756,278 | K21: 2 | L21: Y | M21: no | N21: yes | O21: 0 | P21: 312 | R21: 20819.87 | S21: Credit Card | T21: ₹247,291 | U21: 6 | V21: 65.4 | W21: 12.5 | X21: Single | Y21: 1 | Z21: Rented | AA21: 29.0 | AB21: 756149.0 | AC21: 0 | AD21: N | AE21: 36 | AH21: Verified
A22: CUST00021 | B22: Rekha Rao | C22: 9991990632 | D22: rekha.rao958 at gmail.com | E22: 38 | F22: F | G22: Ahmedabad | H22: Business Owner | I22: Self-Employed | J22: 1889596 | K22: 1 | L22: yes | M22: no | N22: N | O22: no | P22: 663 | Q22: ₹904,548 | R22: 27410.56 | S22: Car Loan | U22: 1 | V22: 54.1 | W22: 3.0 | X22: Married | Y22: 1 | Z22: Rented | AA22: 4.3 | AC22: 1 | AD22: false | AE22: 24 | AF22: 939712.0 | AH22: Verified
A23: CUST00022 | B23: Rahul Iyer | C23: 09812921644 | D23: rahul.iyer596@outlook.com | F23: F | G23: Indore | H23: Freelancer | I23: Self-Employed | J23: 1,687,439 | K23: 1 | L23: Y | M23: 0 | N23: No | O23: NO | P23: 497 | Q23: 319480.74 | R23: 5414.93 | S23: personal loan | T23: 250845 | U23: 0 | V23: 51.0 | W23: 10.9 | X23: Divorced | Y23: 2 | Z23: Owned | AA23: 3.3 | AB23: 320612.0 | AC23: 0 | AD23: NO | AE23: 60 | AG23: 10/29/2025 | AH23: Verified
